Workbook

Sheet Tabela 1
A1: Początkowa wartość zakresu mutacji | B1: Lp. | C1: x1* | D1: x2* | E1: y* | F1: Liczba wywołań funkcji celu | G1: Minimum globalne [tak/nie]
A2: 0.01 | B2: 1 | C2: 0.00168657 | D2: -0.000410691 | E2: 9.59462e-05 | F2: 1550 | G2: 1
B3: 2 | C3: -0.00115888 | D3: 0.000113524 | E3: 4.3175e-05 | F3: 350 | G3: 1
B4: 3 | C4: 0.000638384 | D4: -0.000241155 | E4: 1.48287e-05 | F4: 750 | G4: 1
B5: 4 | C5: -0.000570282 | D5: -0.000415981 | E5: 1.58659e-05 | F5: 750 | G5: 1
B6: 5 | C6: 0.000712223 | D6: -0.000111827 | E6: 1.65506e-05 | F6: 650 | G6: 1
B7: 6 | C7: 0.000748433 | D7: -0.000852793 | E7: 4.09942e-05 | F7: 650 | G7: 1
B8: 7 | C8: -0.00169295 | D8: 6.32044e-05 | E8: 9.1389e-05 | F8: 650 | G8: 1
B9: 8 | C9: 0.000206466 | D9: 0.000107612 | E9: 1.72614e-06 | F9: 650 | G9: 1
B10: 9 | C10: -0.000246626 | D10: 6.17922e-05 | E10: 2.05838e-06 | F10: 650 | G10: 1
B11: 10 | C11: -0.000263555 | D11: 0.00171759 | E11: 9.61493e-05 | F11: 850 | G11: 1
B12: 11 | C12: 0.000375377 | D12: -1.21208e-05 | E12: 4.49154e-06 | F12: 1050 | G12: 1
B13: 12 | C13: -0.000173628 | D13: -5.53061e-05 | E13: 1.05735e-06 | F13: 750 | G13: 1
B14: 13 | C14: -0.00148349 | D14: -0.000801957 | E14: 9.05555e-05 | F14: 750 | G14: 1
... B101: 100 | C101: 0.000158523 | D101: 2.13489e-05 | E101: 8.14703e-07 | F101: 450 | G101: 1
A102: 0.1 | B102: 1 | C102: -0.000551755 | D102: -0.000504325 | E102: 1.77928e-05 | F102: 650 | G102: 1
B103: 2 | C103: 0.000992112 | D103: 0.000382661 | E103: 3.60047e-05 | F103: 750 | G103: 1
B104: 3 | C104: 0.00126825 | D104: -0.000928966 | E104: 7.86958e-05 | F104: 650 | G104: 1
B105: 4 | C105: -0.000291482 | D105: -0.000278591 | E105: 5.17678e-06 | F105: 1850 | G105: 1
B106: 5 | C106: -0.000109928 | D106: -0.000886194 | E106: 2.53919e-05 | F106: 750 | G106: 1
B107: 6 | C107: 0.000407817 | D107: 0.000482048 | E107: 1.26951e-05 | F107: 850 | G107: 1
B108: 7 | C108: 0.000286788 | D108: -0.00157166 | E108: 8.12729e-05 | F108: 850 | G108: 1
B109: 8 | C109: -0.000163626 | D109: 0.000802468 | E109: 2.13576e-05 | F109: 750 | G109: 1
B110: 9 | C110: -0.000251914 | D110: -2.16985e-05 | E110: 2.03574e-06 | F110: 1150 | G110: 1
B111: 10 | C111: 4.45208e-05 | D111: 0.00164967 | E111: 8.67185e-05 | F111: 550 | G111: 1
B112: 11 | C112: -0.00072624 | D112: -1.52781e-05 | E112: 1.68019e-05 | F112: 650 | G112: 1
B113: 12 | C113: 0.000970636 | D113: -0.000884912 | E113: 5.49346e-05 | F113: 750 | G113: 1
B114: 13 | C114: -0.000549441 | D114: 0.000170606 | E114: 1.05396e-05 | F114: 950 | G114: 1
... B201: 100 | C201: 0.00013767 | D201: 0.000739011 | E201: 1.79938e-05 | F201: 650 | G201: 1
A202: 1 | B202: 1 | C202: -6.28357e-05 | D202: 0.00150226 | E202: 7.19864e-05 | F202: 1050 | G202: 1
B203: 2 | C203: -0.000189828 | D203: -0.000509053 | E203: 9.39893e-06 | F203: 1450 | G203: 1
B204: 3 | C204: 0.00025679 | D204: 0.000185629 | E204: 3.19696e-06 | F204: 1450 | G204: 1
B205: 4 | C205: 0.000362504 | D205: 0.000911506 | E205: 3.06404e-05 | F205: 1250 | G205: 1
B206: 5 | C206: -0.000966326 | D206: 0.00013789 | E206: 3.03394e-05 | F206: 1350 | G206: 1
B207: 6 | C207: 0.000702434 | D207: 0.000900235 | E207: 4.15173e-05 | F207: 1550 | G207: 1
B208: 7 | C208: 0.000412591 | D208: -0.0009169 | E208: 3.21906e-05 | F208: 2250 | G208: 1
B209: 8 | C209: 0.000544647 | D209: 0.000984201 | E209: 4.029e-05 | F209: 1450 | G209: 1
B210: 9 | C210: 0.000319992 | D210: 0.000284917 | E210: 5.84541e-06 | F210: 1550 | G210: 1
B211: 10 | C211: 0.000441899 | D211: 0.000999258 | E211: 3.80131e-05 | F211: 1450 | G211: 1
B212: 11 | C212: 0.000628233 | D212: -0.000155722 | E212: 1.33396e-05 | F212: 950 | G212: 1
...

Sheet Tabela 2
A1: Początkowa wartość zakresu mutacji | B1: x1* | C1: x2* | D1: y* | E1: Liczba wywołań funkcji celu | F1: Liczba minimów globalnych
A2: 0.01 | B2: =AVERAGE('Tabela 1'!C2:C101) -> 4.9572753e-05 | C2: =AVERAGE('Tabela 1'!D2:D101) -> 0.00015213204 | D2: =AVERAGE('Tabela 1'!E2:E101) -> 3.9663353e-05 | E2: =AVERAGE('Tabela 1'!F2:F101) -> 754 | F2: =AVERAGE('Tabela 1'!G2:G101) -> 1
A3: 0.1 | B3: =AVERAGE('Tabela 1'!C102:C203) -> -3.4083078e-05 | C3: =AVERAGE('Tabela 1'!D102:D203) -> 1.4075785e-05 | D3: =AVERAGE('Tabela 1'!E102:E203) -> 3.9376968e-05 | E3: =AVERAGE('Tabela 1'!F102:F203) -> 942.15686 | F3: =AVERAGE('Tabela 1'!G102:G203) -> 1
A4: 1 | B4: =AVERAGE('Tabela 1'!C203:C302) -> 0.00016051044 | C4: =AVERAGE('Tabela 1'!D203:D302) -> -0.00010680727 | D4: =AVERAGE('Tabela 1'!E203:E302) -> 4.0322135e-05 | E4: =AVERAGE('Tabela 1'!F203:F302) -> 1411 | F4: =AVERAGE('Tabela 1'!G203:G302) -> 1
A5: 10 | B5: =AVERAGE('Tabela 1'!C303:C402) -> 5.8693483e-05 | C5: =AVERAGE('Tabela 1'!D303:D402) -> 6.4370304e-05 | D5: =AVERAGE('Tabela 1'!E303:E402) -> 4.0739151e-05 | E5: =AVERAGE('Tabela 1'!F303:F402) -> 2043 | F5: =AVERAGE('Tabela 1'!G303:G402) -> 1
A6: 100 | B6: =AVERAGE('Tabela 1'!C403:C502) -> -4.5682065e-05 | C6: =AVERAGE('Tabela 1'!D403:D502) -> 0.00014435298 | D6: =AVERAGE('Tabela 1'!E403:E502) -> 4.2954376e-05 | E6: =AVERAGE('Tabela 1'!F403:F502) -> 4358.0808 | F6: =AVERAGE('Tabela 1'!G403:G502) -> 1

Sheet Tabela 3
A1: b1* | B1: b2* | C1: y* | D1: Liczba wywołań funkcji celu

Sheet Symulacja
A1: t | B1: Doświadczenie | D1: Symulacja
B2: x1 | C2: x2 | D2: x1 | E2: x2
A3: 0 | B3: 0 | C3: 0
A4: 0.1 | B4: 0.00110938 | C4: 0.0119141
A5: 0.2 | B5: 0.00798487 | C5: 0.0455522
A6: 0.3 | B6: 0.0241615 | C6: 0.0982328
A7: 0.4 | B7: 0.0513794 | C7: 0.16773
A8: 0.5 | B8: 0.0901357 | C8: 0.252112
A9: 0.6 | B9: 0.140098 | C9: 0.349629
A10: 0.7 | B10: 0.200406 | C10: 0.458631
A11: 0.8 | B11: 0.269888 | C11: 0.577523
A12: 0.9 | B12: 0.347206 | C12: 0.704734
A13: 1 | B13: 0.430958 | C13: 0.838709
A14: 1.1 | B14: 0.519743 | C14: 0.977901
... A1003: 100 | B1003: 1.25 | C1003: 2.08333
